<?xml version="1.0" encoding="utf-8"?>
<!-- This URDF was automatically created by SolidWorks to URDF Exporter! Originally created by Stephen Brawner (brawner@gmail.com) 
     Commit Version: 1.6.0-4-g7f85cfe  Build Version: 1.6.7995.38578
     For more information, please see http://wiki.ros.org/sw_urdf_exporter -->
<robot
  name="engineer_manipulator_framed"
  xmlns:xacro="http://wiki.ros.org/xacro">

  <xacro:macro name="engineer_manipulator_framed">

  <link
    name="arm_base_link">
    <inertial>
      <origin
        xyz="-0.02624 -0.018282 0.25067"
        rpy="0 0 0" />
      <mass
        value="3.4509" />
      <inertia
        ixx="0.030137"
        ixy="-1.2844E-07"
        ixz="-3.1208E-06"
        iyy="0.030724"
        iyz="3.4634E-08"
        izz="0.0009827" />
    </inertial>
    <visual>
      <origin
        xyz="0 0 0"
        rpy="0 0 0" />
      <geometry>
        <mesh
          filename="package://sp_description/meshes/engineer_framed/engineer_manipulator_framed/arm_base_link.STL" />
      </geometry>
      <material
        name="">
        <color
          rgba="1 1 1 1" />
      </material>
    </visual>
    <collision>
      <origin
        xyz="0 0 0"
        rpy="0 0 0" />
      <geometry>
        <mesh
          filename="package://sp_description/meshes/engineer_framed/engineer_manipulator_framed/arm_base_link.STL" />
      </geometry>
    </collision>
  </link>
  <link
    name="link1">
    <inertial>
      <origin
        xyz="-0.046418 -0.011017 0.39513"
        rpy="0 0 0" />
      <mass
        value="3.3312" />
      <inertia
        ixx="0.0042512"
        ixy="-2.4588E-07"
        ixz="4.5056E-06"
        iyy="0.047104"
        iyz="-5.1474E-08"
        izz="0.050684" />
    </inertial>
    <visual>
      <origin
        xyz="0 0 0"
        rpy="0 0 0" />
      <geometry>
        <mesh
          filename="package://sp_description/meshes/engineer_framed/engineer_manipulator_framed/link1.STL" />
      </geometry>
      <material
        name="">
        <color
          rgba="0.79216 0.81961 0.93333 1" />
      </material>
    </visual>
    <collision>
      <origin
        xyz="0 0 0"
        rpy="0 0 0" />
      <geometry>
        <mesh
          filename="package://sp_description/meshes/engineer_framed/engineer_manipulator_framed/link1.STL" />
      </geometry>
    </collision>
  </link>
  <joint
    name="joint1"
    type="prismatic">
    <origin
      xyz="0 0 0"
      rpy="0 0 0" />
    <parent
      link="arm_base_link" />
    <child
      link="link1" />
    <axis
      xyz="0 0 1" />
    <limit
      lower="-0.2012"
      upper="0"
      effort="20"
      velocity="6" />
  </joint>
  <link
    name="link2">
    <inertial>
      <origin
        xyz="0.73763 -0.012605 0.269937"
        rpy="0 0 0" />
      <mass
        value="3.3677" />
      <inertia
        ixx="0.00060317"
        ixy="-1.317E-07"
        ixz="-5.0363E-06"
        iyy="0.059389"
        iyz="2.5076E-07"
        izz="0.059509" />
    </inertial>
    <visual>
      <origin
        xyz="0 0 0"
        rpy="0 0 0" />
      <geometry>
        <mesh
          filename="package://sp_description/meshes/engineer_framed/engineer_manipulator_framed/link2.STL" />
      </geometry>
      <material
        name="">
        <color
          rgba="0.77647 0.75686 0.73725 1" />
      </material>
    </visual>
    <collision>
      <origin
        xyz="0 0 0"
        rpy="0 0 0" />
      <geometry>
        <mesh
          filename="package://sp_description/meshes/engineer_framed/engineer_manipulator_framed/link2.STL" />
      </geometry>
    </collision>
  </link>
  <joint
    name="joint2"
    type="prismatic">
    <origin
      xyz="-0.273 0 0.3831"
      rpy="0 0 0" />
    <parent
      link="link1" />
    <child
      link="link2" />
    <axis
      xyz="-1 0 0" />
    <limit
      lower="0"
      upper="0.86634"
      effort="20"
      velocity="6" />
  </joint>
  <link
    name="link3">
    <inertial>
      <origin
        xyz="0.51093 0.000566 0.038621"
        rpy="0 0 0" />
      <mass
        value="0.53167" />
      <inertia
        ixx="0.0064934"
        ixy="-2.3958E-07"
        ixz="8.5458E-09"
        iyy="9.996E-05"
        iyz="2.0423E-08"
        izz="0.0065666" />
    </inertial>
    <visual>
      <origin
        xyz="0 0 0"
        rpy="0 0 0" />
      <geometry>
        <mesh
          filename="package://sp_description/meshes/engineer_framed/engineer_manipulator_framed/link3.STL" />
      </geometry>
      <material
        name="">
        <color
          rgba="0.79216 0.81961 0.93333 1" />
      </material>
    </visual>
    <collision>
      <origin
        xyz="0 0 0"
        rpy="0 0 0" />
      <geometry>
        <mesh
          filename="package://sp_description/meshes/engineer_framed/engineer_manipulator_framed/link3.STL" />
      </geometry>
    </collision>
  </link>
  <joint
    name="joint3"
    type="prismatic">
    <origin
      xyz="0.42794 0 0.072"
      rpy="0 0 0" />
    <parent
      link="link2" />
    <child
      link="link3" />
    <axis
      xyz="-1 0 0" />
    <limit
      lower="0"
      upper="0.4754"
      effort="20"
      velocity="6" />
  </joint>
  <link
    name="link4">
    <inertial>
      <origin
        xyz="0.0022176 0.055912 0.11366"
        rpy="0 0 0" />
      <mass
        value="2.56" />
      <inertia
        ixx="0.0074237"
        ixy="-1.2559E-06"
        ixz="-6.9104E-06"
        iyy="0.00083452"
        iyz="-5.1569E-07"
        izz="0.0075779" />
    </inertial>
    <visual>
      <origin
        xyz="0 0 0"
        rpy="0 0 0" />
      <geometry>
        <mesh
          filename="package://sp_description/meshes/engineer_framed/engineer_manipulator_framed/link4.STL" />
      </geometry>
      <material
        name="">
        <color
          rgba="0.77647 0.75686 0.73725 1" />
      </material>
    </visual>
    <collision>
      <origin
        xyz="0 0 0"
        rpy="0 0 0" />
      <geometry>
        <mesh
          filename="package://sp_description/meshes/engineer_framed/engineer_manipulator_framed/link4.STL" />
      </geometry>
    </collision>
  </link>
  <joint
    name="joint4"
    type="prismatic">
    <origin
      xyz="0.5097 0 0.034"
      rpy="0 0 0" />
    <parent
      link="link3" />
    <child
      link="link4" />
    <axis
      xyz="0 1 0" />
    <limit
      lower="-0.185"
      upper="0.185"
      effort="20"
      velocity="6" />
  </joint>
  <link
    name="link5">
    <inertial>
      <origin
        xyz="0.037482 0.0011554 -0.028017"
        rpy="0 0 0" />
      <mass
        value="0.31809" />
      <inertia
        ixx="0.00016271"
        ixy="-1.8762E-07"
        ixz="-1.4951E-07"
        iyy="9.8184E-05"
        iyz="4.2357E-09"
        izz="9.9246E-05" />
    </inertial>
    <visual>
      <origin
        xyz="0 0 0"
        rpy="0 0 0" />
      <geometry>
        <mesh
          filename="package://sp_description/meshes/engineer_framed/engineer_manipulator_framed/link5.STL" />
      </geometry>
      <material
        name="">
        <color
          rgba="0.77647 0.75686 0.73725 1" />
      </material>
    </visual>
    <collision>
      <origin
        xyz="0 0 0"
        rpy="0 0 0" />
      <geometry>
        <mesh
          filename="package://sp_description/meshes/engineer_framed/engineer_manipulator_framed/link5.STL" />
      </geometry>
    </collision>
  </link>
  <joint
    name="joint5"
    type="revolute">
    <origin
      xyz="0 -0.019 0.128"
      rpy="1.5708 0 0" />
    <parent
      link="link4" />
    <child
      link="link5" />
    <axis
      xyz="0 0 1" />
    <limit
      lower="0"
      upper="3.14"
      effort="20"
      velocity="6" />
  </joint>
  <link
    name="link6">
    <inertial>
      <origin
        xyz="0.0001049 0.14059 -0.0055479"
        rpy="0 0 0" />
      <mass
        value="0.63735" />
      <inertia
        ixx="0.00027146"
        ixy="1.1047E-08"
        ixz="2.2272E-07"
        iyy="0.00027079"
        iyz="2.9582E-06"
        izz="0.0002496" />
    </inertial>
    <visual>
      <origin
        xyz="0 0 0"
        rpy="0 0 0" />
      <geometry>
        <mesh
          filename="package://sp_description/meshes/engineer_framed/engineer_manipulator_framed/link6.STL" />
      </geometry>
      <material
        name="">
        <color
          rgba="0.77647 0.75686 0.73725 1" />
      </material>
    </visual>
    <collision>
      <origin
        xyz="0 0 0"
        rpy="0 0 0" />
      <geometry>
        <mesh
          filename="package://sp_description/meshes/engineer_framed/engineer_manipulator_framed/link6.STL" />
      </geometry>
    </collision>
  </link>
  <joint
    name="joint6"
    type="revolute">
    <origin
      xyz="0.071794 0 -0.028"
      rpy="0 1.5708 0" />
    <parent
      link="link5" />
    <child
      link="link6" />
    <axis
      xyz="0 0 -1" />
    <limit
      lower="-1.57"
      upper="1.57"
      effort="20"
      velocity="6" />
  </joint>
  <link
    name="link7">
    <inertial>
      <origin
        xyz="-0.0013183 -0.057506 0.034955"
        rpy="0 0 0" />
      <mass
        value="0.19723" />
      <inertia
        ixx="0.00010859"
        ixy="-1.059E-06"
        ixz="2.4478E-08"
        iyy="6.2669E-05"
        iyz="3.9133E-08"
        izz="0.00015495" />
    </inertial>
    <visual>
      <origin
        xyz="0 0 0"
        rpy="0 0 0" />
      <geometry>
        <mesh
          filename="package://sp_description/meshes/engineer_framed/engineer_manipulator_framed/link7.STL" />
      </geometry>
      <material
        name="">
        <color
          rgba="0.69804 0.69804 0.69804 1" />
      </material>
    </visual>
    <collision>
      <origin
        xyz="0 0 0"
        rpy="0 0 0" />
      <geometry>
        <mesh
          filename="package://sp_description/meshes/engineer_framed/engineer_manipulator_framed/link7.STL" />
      </geometry>
    </collision>
  </link>
  <joint
    name="joint7"
    type="revolute">
    <origin
      xyz="0 0.17579 -0.071794"
      rpy="1.5708 0 3.1416" />
    <parent
      link="link6" />
    <child
      link="link7" />
    <axis
      xyz="0 0 1" />
    <limit
      lower="-1.57"
      upper="1.57"
      effort="20"
      velocity="6" />
  </joint>
   </xacro:macro>
</robot>