<?xml version="1.0" encoding="utf-8"?>
<!-- This URDF was automatically created by SolidWorks to URDF Exporter! Originally created by Stephen Brawner (brawner@gmail.com) 
     Commit Version: 1.6.0-4-g7f85cfe  Build Version: 1.6.7995.38578
     For more information, please see http://wiki.ros.org/sw_urdf_exporter -->
<robot
  name="engineer_manipulator_framed"
  xmlns:xacro="http://wiki.ros.org/xacro">
  <xacro:macro name="engineer_manipulator_framed">
  <link
    name="arm_base_link">
    <inertial>
      <origin
        xyz="-0.037522 -0.068476 0.28458"
        rpy="0 0 0" />
      <mass
        value="1.851" />
      <inertia
        ixx="0.013502"
        ixy="1.5471E-07"
        ixz="-1.0797E-06"
        iyy="0.013899"
        iyz="2.8303E-07"
        izz="0.00075044" />
    </inertial>
    <visual>
      <origin
        xyz="0 0 0"
        rpy="0 0 0" />
      <geometry>
        <mesh
          filename="package://sp_description/meshes/engineer_framed/engineer_manipulator_framed/arm_base_link.STL" />
      </geometry>
      <material
        name="">
        <color
          rgba="1 1 1 1" />
      </material>
    </visual>
    <collision>
      <origin
        xyz="0 0 0"
        rpy="0 0 0" />
      <geometry>
        <mesh
          filename="package://sp_description/meshes/engineer_framed/engineer_manipulator_framed/arm_base_link.STL" />
      </geometry>
    </collision>
  </link>
  <link
    name="link1">
    <inertial>
      <origin
        xyz="-0.046385 -0.011064 0.39469"
        rpy="0 0 0" />
      <mass
        value="3.3269" />
      <inertia
        ixx="0.0042506"
        ixy="-2.4588E-07"
        ixz="4.5157E-06"
        iyy="0.047094"
        iyz="-5.1474E-08"
        izz="0.050675" />
    </inertial>
    <visual>
      <origin
        xyz="0 0 0"
        rpy="0 0 0" />
      <geometry>
        <mesh
          filename="package://sp_description/meshes/engineer_framed/engineer_manipulator_framed/link1.STL" />
      </geometry>
      <material
        name="">
        <color
          rgba="0.79216 0.81961 0.93333 1" />
      </material>
    </visual>
    <collision>
      <origin
        xyz="0 0 0"
        rpy="0 0 0" />
      <geometry>
        <mesh
          filename="package://sp_description/meshes/engineer_framed/engineer_manipulator_framed/link1.STL" />
      </geometry>
    </collision>
  </link>
  <joint
    name="joint1"
    type="prismatic">
    <origin
      xyz="0 0 0"
      rpy="0 0 0" />
    <parent
      link="arm_base_link" />
    <child
      link="link1" />
    <axis
      xyz="0 0 1" />
    <limit
      lower="-0.3012"
      upper="0"
      effort="0"
      velocity="0" />
  </joint>
  <link
    name="link2">
    <inertial>
      <origin
        xyz="0.73463 -0.012605 0.039937"
        rpy="0 0 0" />
      <mass
        value="3.3677" />
      <inertia
        ixx="0.00060317"
        ixy="-1.317E-07"
        ixz="-5.0363E-06"
        iyy="0.059389"
        iyz="2.5076E-07"
        izz="0.059509" />
    </inertial>
    <visual>
      <origin
        xyz="0 0 0"
        rpy="0 0 0" />
      <geometry>
        <mesh
          filename="package://sp_description/meshes/engineer_framed/engineer_manipulator_framed/link2.STL" />
      </geometry>
      <material
        name="">
        <color
          rgba="0.77647 0.75686 0.73725 1" />
      </material>
    </visual>
    <collision>
      <origin
        xyz="0 0 0"
        rpy="0 0 0" />
      <geometry>
        <mesh
          filename="package://sp_description/meshes/engineer_framed/engineer_manipulator_framed/link2.STL" />
      </geometry>
    </collision>
  </link>
  <joint
    name="joint2"
    type="prismatic">
    <origin
      xyz="-0.27 0 0.4126"
      rpy="0 0 0" />
    <parent
      link="link1" />
    <child
      link="link2" />
    <axis
      xyz="-1 0 0" />
    <limit
      lower="0"
      upper="0.4394"
      effort="0"
      velocity="0" />
  </joint>
  <link
    name="link3">
    <inertial>
      <origin
        xyz="0.51092 0.0050158 0.038576"
        rpy="0 0 0" />
      <mass
        value="0.53637" />
      <inertia
        ixx="0.006721"
        ixy="-1.2751E-06"
        ixz="5.8146E-09"
        iyy="0.00010173"
        iyz="3.4689E-08"
        izz="0.0067953" />
    </inertial>
    <visual>
      <origin
        xyz="0 0 0"
        rpy="0 0 0" />
      <geometry>
        <mesh
          filename="package://sp_description/meshes/engineer_framed/engineer_manipulator_framed/link3.STL" />
      </geometry>
      <material
        name="">
        <color
          rgba="0.79216 0.81961 0.93333 1" />
      </material>
    </visual>
    <collision>
      <origin
        xyz="0 0 0"
        rpy="0 0 0" />
      <geometry>
        <mesh
          filename="package://sp_description/meshes/engineer_framed/engineer_manipulator_framed/link3.STL" />
      </geometry>
    </collision>
  </link>
  <joint
    name="joint3"
    type="prismatic">
    <origin
      xyz="0.42494 0 0.042"
      rpy="0 0 0" />
    <parent
      link="link2" />
    <child
      link="link3" />
    <axis
      xyz="-1 0 0" />
    <limit
      lower="0"
      upper="0.4754"
      effort="0"
      velocity="0" />
  </joint>
  <link
    name="link4">
    <inertial>
      <origin
        xyz="-0.004492 0.0012594 0.076929"
        rpy="0 0 0" />
      <mass
        value="1.4781" />
      <inertia
        ixx="0.00699"
        ixy="-4.5494E-07"
        ixz="-1.6934E-07"
        iyy="0.00040962"
        iyz="-2.7173E-07"
        izz="0.006972" />
    </inertial>
    <visual>
      <origin
        xyz="0 0 0"
        rpy="0 0 0" />
      <geometry>
        <mesh
          filename="package://sp_description/meshes/engineer_framed/engineer_manipulator_framed/link4.STL" />
      </geometry>
      <material
        name="">
        <color
          rgba="0.77647 0.75686 0.73725 1" />
      </material>
    </visual>
    <collision>
      <origin
        xyz="0 0 0"
        rpy="0 0 0" />
      <geometry>
        <mesh
          filename="package://sp_description/meshes/engineer_framed/engineer_manipulator_framed/link4.STL" />
      </geometry>
    </collision>
  </link>
  <joint
    name="joint4"
    type="prismatic">
    <origin
      xyz="0.5097 0 0.034"
      rpy="0 0 0" />
    <parent
      link="link3" />
    <child
      link="link4" />
    <axis
      xyz="0 1 0" />
    <limit
      lower="-0.17022"
      upper="0.13858"
      effort="0"
      velocity="0" />
  </joint>
  <link
    name="link5">
    <inertial>
      <origin
        xyz="0.037482 -0.0011554 0.028017"
        rpy="0 0 0" />
      <mass
        value="0.31809" />
      <inertia
        ixx="0.00016271"
        ixy="1.8762E-07"
        ixz="1.4951E-07"
        iyy="9.8184E-05"
        iyz="4.2357E-09"
        izz="9.9246E-05" />
    </inertial>
    <visual>
      <origin
        xyz="0 0 0"
        rpy="0 0 0" />
      <geometry>
        <mesh
          filename="package://sp_description/meshes/engineer_framed/engineer_manipulator_framed/link5.STL" />
      </geometry>
      <material
        name="">
        <color
          rgba="0.77647 0.75686 0.73725 1" />
      </material>
    </visual>
    <collision>
      <origin
        xyz="0 0 0"
        rpy="0 0 0" />
      <geometry>
        <mesh
          filename="package://sp_description/meshes/engineer_framed/engineer_manipulator_framed/link5.STL" />
      </geometry>
    </collision>
  </link>
  <joint
    name="joint5"
    type="revolute">
    <origin
      xyz="0 -0.007 0.128"
      rpy="-1.5708 0 0" />
    <parent
      link="link4" />
    <child
      link="link5" />
    <axis
      xyz="0 0 -1" />
    <limit
      lower="0"
      upper="3.14"
      effort="0"
      velocity="0" />
  </joint>
  <link
    name="link6">
    <inertial>
      <origin
        xyz="0.14216 -0.00011579 -0.0086719"
        rpy="0 0 0" />
      <mass
        value="0.66912" />
      <inertia
        ixx="0.00027285"
        ixy="1.2504E-08"
        ixz="2.9576E-06"
        iyy="0.00027332"
        iyz="-2.2374E-07"
        izz="0.00025157" />
    </inertial>
    <visual>
      <origin
        xyz="0 0 0"
        rpy="0 0 0" />
      <geometry>
        <mesh
          filename="package://sp_description/meshes/engineer_framed/engineer_manipulator_framed/link6.STL" />
      </geometry>
      <material
        name="">
        <color
          rgba="0.77647 0.75686 0.73725 1" />
      </material>
    </visual>
    <collision>
      <origin
        xyz="0 0 0"
        rpy="0 0 0" />
      <geometry>
        <mesh
          filename="package://sp_description/meshes/engineer_framed/engineer_manipulator_framed/link6.STL" />
      </geometry>
    </collision>
  </link>
  <joint
    name="joint6"
    type="revolute">
    <origin
      xyz="0.071794 0 0.028"
      rpy="-1.5708 0 -1.5708" />
    <parent
      link="link5" />
    <child
      link="link6" />
    <axis
      xyz="0 0 -1" />
    <limit
      lower="-1.57"
      upper="+1.57"
      effort="0"
      velocity="0" />
  </joint>
  <link
    name="link7">
    <inertial>
      <origin
        xyz="-0.057503 0.0014691 0.022736"
        rpy="0 0 0" />
      <mass
        value="0.19723" />
      <inertia
        ixx="6.2669E-05"
        ixy="1.059E-06"
        ixz="3.9133E-08"
        iyy="0.00010859"
        iyz="-2.4478E-08"
        izz="0.00015495" />
    </inertial>
    <visual>
      <origin
        xyz="0 0 0"
        rpy="0 0 0" />
      <geometry>
        <mesh
          filename="package://sp_description/meshes/engineer_framed/engineer_manipulator_framed/link7.STL" />
      </geometry>
      <material
        name="">
        <color
          rgba="0.69804 0.69804 0.69804 1" />
      </material>
    </visual>
    <collision>
      <origin
        xyz="0 0 0"
        rpy="0 0 0" />
      <geometry>
        <mesh
          filename="package://sp_description/meshes/engineer_framed/engineer_manipulator_framed/link7.STL" />
      </geometry>
    </collision>
  </link>
  <joint
    name="joint7"
    type="revolute">
    <origin
      xyz="0.18801 0.00015076 -0.071797"
      rpy="0 -1.5708 0" />
    <parent
      link="link6" />
    <child
      link="link7" />
    <axis
      xyz="0 0 1" />
    <limit
      lower="-1.57"
      upper="+1.57"
      effort="0"
      velocity="0" />
  </joint>
  </xacro:macro>
</robot>