<?xml version="1.0" ?>
<!-- =================================================================================== -->
<!-- |    This document was autogenerated by xacro from /home/lyc/VisualOdometry/src/sp_description/urdf/engineer_framed/engineer_framed.xacro | -->
<!-- |    EDITING THIS FILE BY HAND IS NOT RECOMMENDED                                 | -->
<!-- =================================================================================== -->
<robot name="engineer_framed">
    <transmission name="trans_joint1">
        <type>transmission_interface/SimpleTransmission</type>
        <actuator name="joint1_motor">
            <mechanicalReduction>1.5</mechanicalReduction>
            <hardwareInterface>hardware_interface/PositionJointInterface</hardwareInterface>
        </actuator>
        <joint name="joint1">
            <hardwareInterface>hardware_interface/PositionJointInterface</hardwareInterface>
        </joint>
    </transmission>
    <transmission name="trans_joint2">
        <type>transmission_interface/SimpleTransmission</type>
        <actuator name="joint2_motor">
            <mechanicalReduction>6</mechanicalReduction>
            <hardwareInterface>hardware_interface/PositionJointInterface</hardwareInterface>
        </actuator>
        <joint name="joint2">
            <hardwareInterface>hardware_interface/PositionJointInterface</hardwareInterface>
        </joint>
    </transmission>
    <transmission name="trans_joint3">
        <type>transmission_interface/SimpleTransmission</type>
        <actuator name="joint3_motor">
            <mechanicalReduction>6</mechanicalReduction>
            <hardwareInterface>hardware_interface/PositionJointInterface</hardwareInterface>
        </actuator>
        <joint name="joint3">
            <hardwareInterface>hardware_interface/PositionJointInterface</hardwareInterface>
        </joint>
    </transmission>
    <transmission name="trans_joint4">
        <type>transmission_interface/SimpleTransmission</type>
        <actuator name="joint4_motor">
            <mechanicalReduction>1</mechanicalReduction>
            <hardwareInterface>hardware_interface/PositionJointInterface</hardwareInterface>
        </actuator>
        <joint name="joint4">
            <hardwareInterface>hardware_interface/PositionJointInterface</hardwareInterface>
        </joint>
    </transmission>
    <transmission name="trans_joint5">
        <type>transmission_interface/SimpleTransmission</type>
        <actuator name="joint5_motor">
            <mechanicalReduction>1</mechanicalReduction>
            <hardwareInterface>hardware_interface/PositionJointInterface</hardwareInterface>
        </actuator>
        <joint name="joint5">
            <hardwareInterface>hardware_interface/PositionJointInterface</hardwareInterface>
        </joint>
    </transmission>
    <transmission name="trans_joint6">
        <type>transmission_interface/SimpleTransmission</type>
        <actuator name="joint6_motor">
            <mechanicalReduction>1</mechanicalReduction>
            <hardwareInterface>hardware_interface/PositionJointInterface</hardwareInterface>
        </actuator>
        <joint name="joint6">
            <hardwareInterface>hardware_interface/PositionJointInterface</hardwareInterface>
        </joint>
    </transmission>
    <transmission name="trans_joint7">
        <type>transmission_interface/SimpleTransmission</type>
        <actuator name="joint7_motor">
            <mechanicalReduction>599.99</mechanicalReduction>
            <hardwareInterface>hardware_interface/PositionJointInterface</hardwareInterface>
        </actuator>
        <joint name="joint7">
            <hardwareInterface>hardware_interface/PositionJointInterface</hardwareInterface>
        </joint>
    </transmission>
    <!--<gazebo>
        <plugin name="gazebo_ros_vacuum_gripper" filename="libgazebo_ros_vacuum_gripper.so">
            <robotNamespace>/vacuum_gripper</robotNamespace>
            <bodyName>vacuum_gripper</bodyName>
            <topicName>grasping</topicName>
            <maxForce>100</maxForce>
            <maxDistance>0.05</maxDistance>
            <minDistance>0.01</minDistance>
        </plugin>
    </gazebo>	
    <gazebo reference="vacuum_gripper">
        <mu1>50</mu1>
        <mu2>50</mu2>
　　　   <minDepth>0.003</minDepth>
        <maxVel>0</maxVel>
        <kp>10000000000000.0</kp>
        <kd>1.0</kd>
        <ki>2.0</ki>
        <material>Gazebo/Grey</material>
    </gazebo>-->
    <link name="arm_base_link">
        <inertial>
            <origin rpy="0 0 0" xyz="-0.037522 -0.068476 0.28458" />
            <mass value="1.851" />
            <inertia ixx="0.013502" ixy="1.5471E-07" ixz="-1.0797E-06" iyy="0.013899" iyz="2.8303E-07" izz="0.00075044" />
        </inertial>
        <visual>
            <origin rpy="0 0 0" xyz="0 0 0" />
            <geometry>
                <mesh filename="package://sp_description/meshes/engineer_framed/engineer_manipulator_framed/arm_base_link.STL" />
            </geometry>
            <material name="">
                <color rgba="1 1 1 1" />
            </material>
        </visual>
        <collision>
            <origin rpy="0 0 0" xyz="0 0 0" />
            <geometry>
                <mesh filename="package://sp_description/meshes/engineer_framed/engineer_manipulator_framed/arm_base_link.STL" />
            </geometry>
        </collision>
    </link>
    <link name="link1">
        <inertial>
            <origin rpy="0 0 0" xyz="-0.046385 -0.011064 0.39469" />
            <mass value="3.3269" />
            <inertia ixx="0.0042506" ixy="-2.4588E-07" ixz="4.5157E-06" iyy="0.047094" iyz="-5.1474E-08" izz="0.050675" />
        </inertial>
        <visual>
            <origin rpy="0 0 0" xyz="0 0 0" />
            <geometry>
                <mesh filename="package://sp_description/meshes/engineer_framed/engineer_manipulator_framed/link1.STL" />
            </geometry>
            <material name="">
                <color rgba="0.79216 0.81961 0.93333 1" />
            </material>
        </visual>
        <collision>
            <origin rpy="0 0 0" xyz="0 0 0" />
            <geometry>
                <mesh filename="package://sp_description/meshes/engineer_framed/engineer_manipulator_framed/link1.STL" />
            </geometry>
        </collision>
    </link>
    <joint name="joint1" type="prismatic">
        <origin rpy="0 0 0" xyz="0 0 0" />
        <parent link="arm_base_link" />
        <child link="link1" />
        <axis xyz="0 0 1" />
        <limit effort="0" lower="-0.3012" upper="0" velocity="0" />
    </joint>
    <link name="link2">
        <inertial>
            <origin rpy="0 0 0" xyz="0.73463 -0.012605 0.039937" />
            <mass value="3.3677" />
            <inertia ixx="0.00060317" ixy="-1.317E-07" ixz="-5.0363E-06" iyy="0.059389" iyz="2.5076E-07" izz="0.059509" />
        </inertial>
        <visual>
            <origin rpy="0 0 0" xyz="0 0 0" />
            <geometry>
                <mesh filename="package://sp_description/meshes/engineer_framed/engineer_manipulator_framed/link2.STL" />
            </geometry>
            <material name="">
                <color rgba="0.77647 0.75686 0.73725 1" />
            </material>
        </visual>
        <collision>
            <origin rpy="0 0 0" xyz="0 0 0" />
            <geometry>
                <mesh filename="package://sp_description/meshes/engineer_framed/engineer_manipulator_framed/link2.STL" />
            </geometry>
        </collision>
    </link>
    <joint name="joint2" type="prismatic">
        <origin rpy="0 0 0" xyz="-0.27 0 0.4126" />
        <parent link="link1" />
        <child link="link2" />
        <axis xyz="-1 0 0" />
        <limit effort="0" lower="0" upper="0.4394" velocity="0" />
    </joint>
    <link name="link3">
        <inertial>
            <origin rpy="0 0 0" xyz="0.51092 0.0050158 0.038576" />
            <mass value="0.53637" />
            <inertia ixx="0.006721" ixy="-1.2751E-06" ixz="5.8146E-09" iyy="0.00010173" iyz="3.4689E-08" izz="0.0067953" />
        </inertial>
        <visual>
            <origin rpy="0 0 0" xyz="0 0 0" />
            <geometry>
                <mesh filename="package://sp_description/meshes/engineer_framed/engineer_manipulator_framed/link3.STL" />
            </geometry>
            <material name="">
                <color rgba="0.79216 0.81961 0.93333 1" />
            </material>
        </visual>
        <collision>
            <origin rpy="0 0 0" xyz="0 0 0" />
            <geometry>
                <mesh filename="package://sp_description/meshes/engineer_framed/engineer_manipulator_framed/link3.STL" />
            </geometry>
        </collision>
    </link>
    <joint name="joint3" type="prismatic">
        <origin rpy="0 0 0" xyz="0.42494 0 0.042" />
        <parent link="link2" />
        <child link="link3" />
        <axis xyz="-1 0 0" />
        <limit effort="0" lower="0" upper="0.4754" velocity="0" />
    </joint>
    <link name="link4">
        <inertial>
            <origin rpy="0 0 0" xyz="-0.004492 0.0012594 0.076929" />
            <mass value="1.4781" />
            <inertia ixx="0.00699" ixy="-4.5494E-07" ixz="-1.6934E-07" iyy="0.00040962" iyz="-2.7173E-07" izz="0.006972" />
        </inertial>
        <visual>
            <origin rpy="0 0 0" xyz="0 0 0" />
            <geometry>
                <mesh filename="package://sp_description/meshes/engineer_framed/engineer_manipulator_framed/link4.STL" />
            </geometry>
            <material name="">
                <color rgba="0.77647 0.75686 0.73725 1" />
            </material>
        </visual>
        <collision>
            <origin rpy="0 0 0" xyz="0 0 0" />
            <geometry>
                <mesh filename="package://sp_description/meshes/engineer_framed/engineer_manipulator_framed/link4.STL" />
            </geometry>
        </collision>
    </link>
    <joint name="joint4" type="prismatic">
        <origin rpy="0 0 0" xyz="0.5097 0 0.034" />
        <parent link="link3" />
        <child link="link4" />
        <axis xyz="0 1 0" />
        <limit effort="0" lower="-0.017022" upper="0.013858" velocity="0" />
    </joint>
    <link name="link5">
        <inertial>
            <origin rpy="0 0 0" xyz="0.037482 -0.0011554 0.028017" />
            <mass value="0.31809" />
            <inertia ixx="0.00016271" ixy="1.8762E-07" ixz="1.4951E-07" iyy="9.8184E-05" iyz="4.2357E-09" izz="9.9246E-05" />
        </inertial>
        <visual>
            <origin rpy="0 0 0" xyz="0 0 0" />
            <geometry>
                <mesh filename="package://sp_description/meshes/engineer_framed/engineer_manipulator_framed/link5.STL" />
            </geometry>
            <material name="">
                <color rgba="0.77647 0.75686 0.73725 1" />
            </material>
        </visual>
        <collision>
            <origin rpy="0 0 0" xyz="0 0 0" />
            <geometry>
                <mesh filename="package://sp_description/meshes/engineer_framed/engineer_manipulator_framed/link5.STL" />
            </geometry>
        </collision>
    </link>
    <joint name="joint5" type="revolute">
        <origin rpy="-1.5708 0 0" xyz="0 -0.007 0.128" />
        <parent link="link4" />
        <child link="link5" />
        <axis xyz="0 0 -1" />
        <limit effort="0" lower="0" upper="3.14" velocity="0" />
    </joint>
    <link name="link6">
        <inertial>
            <origin rpy="0 0 0" xyz="0.14216 -0.00011579 -0.0086719" />
            <mass value="0.66912" />
            <inertia ixx="0.00027285" ixy="1.2504E-08" ixz="2.9576E-06" iyy="0.00027332" iyz="-2.2374E-07" izz="0.00025157" />
        </inertial>
        <visual>
            <origin rpy="0 0 0" xyz="0 0 0" />
            <geometry>
                <mesh filename="package://sp_description/meshes/engineer_framed/engineer_manipulator_framed/link6.STL" />
            </geometry>
            <material name="">
                <color rgba="0.77647 0.75686 0.73725 1" />
            </material>
        </visual>
        <collision>
            <origin rpy="0 0 0" xyz="0 0 0" />
            <geometry>
                <mesh filename="package://sp_description/meshes/engineer_framed/engineer_manipulator_framed/link6.STL" />
            </geometry>
        </collision>
    </link>
    <joint name="joint6" type="revolute">
        <origin rpy="-1.5708 0 -1.5708" xyz="0.071794 0 0.028" />
        <parent link="link5" />
        <child link="link6" />
        <axis xyz="0 0 -1" />
        <limit effort="0" lower="-1.57" upper="+1.57" velocity="0" />
    </joint>
    <link name="link7">
        <inertial>
            <origin rpy="0 0 0" xyz="-0.057503 0.0014691 0.022736" />
            <mass value="0.19723" />
            <inertia ixx="6.2669E-05" ixy="1.059E-06" ixz="3.9133E-08" iyy="0.00010859" iyz="-2.4478E-08" izz="0.00015495" />
        </inertial>
        <visual>
            <origin rpy="0 0 0" xyz="0 0 0" />
            <geometry>
                <mesh filename="package://sp_description/meshes/engineer_framed/engineer_manipulator_framed/link7.STL" />
            </geometry>
            <material name="">
                <color rgba="0.69804 0.69804 0.69804 1" />
            </material>
        </visual>
        <collision>
            <origin rpy="0 0 0" xyz="0 0 0" />
            <geometry>
                <mesh filename="package://sp_description/meshes/engineer_framed/engineer_manipulator_framed/link7.STL" />
            </geometry>
        </collision>
    </link>
    <joint name="joint7" type="revolute">
        <origin rpy="0 -1.5708 0" xyz="0.18801 0.00015076 -0.071797" />
        <parent link="link6" />
        <child link="link7" />
        <axis xyz="0 0 1" />
        <limit effort="0" lower="-1.57" upper="+1.57" velocity="0" />
    </joint>
    <link name="base_link">
        <inertial>
            <origin rpy="0 0 0" xyz="0.011757 0.00020017 -0.0013475" />
            <mass value="6.2008" />
            <inertia ixx="0.023597" ixy="-1.3181E-06" ixz="1.6868E-06" iyy="0.039514" iyz="-7.4863E-12" izz="0.059002" />
        </inertial>
        <visual>
            <origin rpy="0 0 0" xyz="0 0 0" />
            <geometry>
                <mesh filename="package://sp_description/meshes/engineer_framed/engineer_chassis/base_link.STL" />
            </geometry>
            <material name="">
                <color rgba="0.65098 0.61961 0.58824 1" />
            </material>
        </visual>
        <collision>
            <origin rpy="0 0 0" xyz="0 0 0" />
            <geometry>
                <mesh filename="package://sp_description/meshes/engineer_framed/engineer_chassis/base_link.STL" />
            </geometry>
        </collision>
    </link>
    <link name="link1_br">
        <inertial>
            <origin rpy="0 0 0" xyz="4.6602E-05 -8.1388E-05 0.014341" />
            <mass value="1.0682" />
            <inertia ixx="0.001219" ixy="-1.5985E-06" ixz="-2.039E-07" iyy="0.0012336" iyz="2.6013E-07" izz="0.0022924" />
        </inertial>
        <visual>
            <origin rpy="0 0 0" xyz="0 0 0" />
            <geometry>
                <mesh filename="package://sp_description/meshes/engineer_framed/engineer_chassis/link1_br.STL" />
            </geometry>
            <material name="">
                <color rgba="0.69804 0.69804 0.69804 1" />
            </material>
        </visual>
        <collision>
            <origin rpy="0 0 0" xyz="0 0 0" />
            <geometry>
                <mesh filename="package://sp_description/meshes/engineer_framed/engineer_chassis/link1_br.STL" />
            </geometry>
        </collision>
    </link>
    <joint name="joint1_br" type="continuous">
        <origin rpy="1.5708 0 0" xyz="-0.1767 -0.2005 -0.045089" />
        <parent link="base_link" />
        <child link="link1_br" />
        <axis xyz="0 0 1" />
    </joint>
    <link name="link2_bl">
        <inertial>
            <origin rpy="0 0 0" xyz="-9.0212E-05 0.00035813 0.014094" />
            <mass value="1.0628" />
            <inertia ixx="0.0012262" ixy="7.4801E-06" ixz="7.6834E-08" iyy="0.001226" iyz="3.2147E-07" izz="0.0022924" />
        </inertial>
        <visual>
            <origin rpy="0 0 0" xyz="0 0 0" />
            <geometry>
                <mesh filename="package://sp_description/meshes/engineer_framed/engineer_chassis/link2_bl.STL" />
            </geometry>
            <material name="">
                <color rgba="0.69804 0.69804 0.69804 1" />
            </material>
        </visual>
        <collision>
            <origin rpy="0 0 0" xyz="0 0 0" />
            <geometry>
                <mesh filename="package://sp_description/meshes/engineer_framed/engineer_chassis/link2_bl.STL" />
            </geometry>
        </collision>
    </link>
    <joint name="joint2_bl" type="continuous">
        <origin rpy="-1.5708 0 0" xyz="-0.1767 0.2005 -0.045089" />
        <parent link="base_link" />
        <child link="link2_bl" />
        <axis xyz="0 0 -1" />
    </joint>
    <link name="link3_fr">
        <inertial>
            <origin rpy="0 0 0" xyz="0.0001525 -0.00025626 0.014179" />
            <mass value="1.0474" />
            <inertia ixx="0.0012184" ixy="7.4058E-06" ixz="9.7389E-08" iyy="0.0012163" iyz="3.1585E-07" izz="0.0022749" />
        </inertial>
        <visual>
            <origin rpy="0 0 0" xyz="0 0 0" />
            <geometry>
                <mesh filename="package://sp_description/meshes/engineer_framed/engineer_chassis/link3_fr.STL" />
            </geometry>
            <material name="">
                <color rgba="0.69804 0.69804 0.69804 1" />
            </material>
        </visual>
        <collision>
            <origin rpy="0 0 0" xyz="0 0 0" />
            <geometry>
                <mesh filename="package://sp_description/meshes/engineer_framed/engineer_chassis/link3_fr.STL" />
            </geometry>
        </collision>
    </link>
    <joint name="joint3_fr" type="continuous">
        <origin rpy="1.5708 0 0" xyz="0.2067 -0.2005 -0.045089" />
        <parent link="base_link" />
        <child link="link3_fr" />
        <axis xyz="0 0 1" />
        <limit effort="0" lower="0" upper="0" velocity="0" />
    </joint>
    <link name="link4_fl">
        <inertial>
            <origin rpy="0 0 0" xyz="0 0 0" />
            <mass value="0" />
            <inertia ixx="0" ixy="0" ixz="0" iyy="0" iyz="0" izz="0" />
        </inertial>
        <visual>
            <origin rpy="0 0 0" xyz="0 0 0" />
            <geometry>
                <mesh filename="package://sp_description/meshes/engineer_framed/engineer_chassis/link4_fl.STL" />
            </geometry>
            <material name="">
                <color rgba="1 1 1 1" />
            </material>
        </visual>
        <collision>
            <origin rpy="0 0 0" xyz="0 0 0" />
            <geometry>
                <mesh filename="package://sp_description/meshes/engineer_framed/engineer_chassis/link4_fl.STL" />
            </geometry>
        </collision>
    </link>
    <joint name="joint4_fl" type="continuous">
        <origin rpy="-1.5708 0 0" xyz="0.20667 0.2005 -0.044983" />
        <parent link="base_link" />
        <child link="link4_fl" />
        <axis xyz="0 0 -1" />
    </joint>
    <joint name="joint_arm2body" type="fixed">
        <axis xyz="0 0 1" />
        <origin rpy="0 0 1.57" xyz="0.011757 0.00020017 -0.0013475" />
        <parent link="base_link" />
        <child link="arm_base_link" />
    </joint>
    <!--在机器人模型的urdf/xacro文件中添加gazebo_ros_control插件-->
    <gazebo>
        <plugin filename="libgazebo_ros_control.so" name="gazebo_ros_control">
            <robotNamespace>/engineer_framed</robotNamespace>
        </plugin>
    </gazebo>
    <transmission name="trans_joint1_br">
        <type>transmission_interface/SimpleTransmission</type>
        <joint name="joint1_br">
            <hardwareInterface>hardware_interface/EffortJointInterface</hardwareInterface>
        </joint>
        <actuator name="joint1_br_motor">
            <hardwareInterface>hardware_interface/EffortJointInterface</hardwareInterface>
            <mechanicalReduction>1</mechanicalReduction>
        </actuator>
    </transmission>
    <transmission name="trans_joint2_bl">
        <type>transmission_interface/SimpleTransmission</type>
        <joint name="joint2_bl">
            <hardwareInterface>hardware_interface/EffortJointInterface</hardwareInterface>
        </joint>
        <actuator name="joint2_bl_motor">
            <hardwareInterface>hardware_interface/EffortJointInterface</hardwareInterface>
            <mechanicalReduction>1</mechanicalReduction>
        </actuator>
    </transmission>
    <transmission name="trans_joint3_fr">
        <type>transmission_interface/SimpleTransmission</type>
        <joint name="joint3_fr">
            <hardwareInterface>hardware_interface/EffortJointInterface</hardwareInterface>
        </joint>
        <actuator name="joint3_fr_motor">
            <hardwareInterface>hardware_interface/EffortJointInterface</hardwareInterface>
            <mechanicalReduction>1</mechanicalReduction>
        </actuator>
    </transmission>
    <transmission name="trans_joint4_fl">
        <type>transmission_interface/SimpleTransmission</type>
        <joint name="joint4_fl">
            <hardwareInterface>hardware_interface/EffortJointInterface</hardwareInterface>
        </joint>
        <actuator name="joint4_fl_motor">
            <hardwareInterface>hardware_interface/EffortJointInterface</hardwareInterface>
            <mechanicalReduction>1</mechanicalReduction>
        </actuator>
    </transmission>
</robot>

