<?xml version="1.0" encoding="utf-8"?>
<!-- This URDF was automatically created by SolidWorks to URDF Exporter! Originally created by Stephen Brawner (brawner@gmail.com) 
     Commit Version: 1.6.0-4-g7f85cfe  Build Version: 1.6.7995.38578
     For more information, please see http://wiki.ros.org/sw_urdf_exporter -->
<robot
  name="engineer_chassis_framed" 
  xmlns:xacro="http://wiki.ros.org/xacro">
  
  <xacro:macro name="engineer_chassis_framed" params="roller_type">

 <link
    name="base_link">
    <inertial>
      <origin
        xyz="-0.0018086 0.00030067 0.12012"
        rpy="0 0 0" />
      <mass
        value="6.3166" />
      <inertia
        ixx="0.02453"
        ixy="-5.3584E-06"
        ixz="1.0636E-06"
        iyy="0.040448"
        iyz="-4.9021E-09"
        izz="0.060871" />
    </inertial>
    <visual>
      <origin
        xyz="0 0 0"
        rpy="0 0 0" />
      <geometry>
        <mesh
          filename="package://sp_description/meshes/engineer_framed/engineer_chassis/base_link.STL" />
      </geometry>
      <material
        name="">
        <color
          rgba="0.65098 0.61961 0.58824 1" />
      </material>
    </visual>
    <collision>
      <origin
        xyz="0 0 0"
        rpy="0 0 0" />
      <geometry>
        <mesh
          filename="package://sp_description/meshes/engineer_framed/engineer_chassis/base_link.STL" />
      </geometry>
    </collision>
  </link>
  <link
    name="link1_br">
    <inertial>
      <origin
        xyz="3.6924E-05 -0.00010328 0.024042"
        rpy="0 0 0" />
      <mass
        value="0.70318" />
      <inertia
        ixx="0.0011574"
        ixy="1.4786E-09"
        ixz="-6.9963E-12"
        iyy="0.001172"
        iyz="1.7156E-09"
        izz="0.0022157" />
    </inertial>
    <visual>
      <origin
        xyz="0 0 0"
        rpy="0 0 0" />
      <geometry>
        <mesh
          filename="package://sp_description/meshes/engineer_framed/engineer_chassis/link1_br.STL" />
      </geometry>
      <material
        name="">
        <color
          rgba="0.69804 0.69804 0.69804 1" />
      </material>
    </visual>
    <collision>
      <origin
        xyz="0 0 0"
        rpy="0 0 0" />
      <geometry>
        <mesh
          filename="package://sp_description/meshes/engineer_framed/engineer_chassis/link1_br.STL" />
      </geometry>
    </collision>
  </link>
  <joint
    name="joint1_br"
    type="continuous">
    <origin
      xyz="-0.1917 -0.2005 0.077"
      rpy="1.5708 -0.088599 0" />
    <parent
      link="base_link" />
    <child
      link="link1_br" />
    <axis
      xyz="0 0 -1" />
  </joint>
  <link
    name="link2_bl">
    <inertial>
      <origin
        xyz="-0.00013404 0.023742 -0.00058016"
        rpy="0 0 0" />
      <mass
        value="0.69776" />
      <inertia
        ixx="0.0011649"
        ixy="1.2388E-09"
        ixz="-7.2836E-06"
        iyy="0.0022157"
        iyz="-1.187E-09"
        izz="0.0011641" />
    </inertial>
    <visual>
      <origin
        xyz="0 0 0"
        rpy="0 0 0" />
      <geometry>
        <mesh
          filename="package://sp_description/meshes/engineer_framed/engineer_chassis/link2_bl.STL" />
      </geometry>
      <material
        name="">
        <color
          rgba="0.69804 0.69804 0.69804 1" />
      </material>
    </visual>
    <collision>
      <origin
        xyz="0 0 0"
        rpy="0 0 0" />
      <geometry>
        <mesh
          filename="package://sp_description/meshes/engineer_framed/engineer_chassis/link2_bl.STL" />
      </geometry>
    </collision>
  </link>
  <joint
    name="joint2_bl"
    type="continuous">
    <origin
      xyz="-0.1917 0.2005 0.077"
      rpy="0 0 0" />
    <parent
      link="base_link" />
    <child
      link="link2_bl" />
    <axis
      xyz="0 1 0" />
  </joint>
  <link
    name="link3_fr">
    <inertial>
      <origin
        xyz="0.00023979 -0.024088 -0.00035815"
        rpy="0 0 0" />
      <mass
        value="0.68237" />
      <inertia
        ixx="0.001157"
        ixy="-1.3127E-09"
        ixz="7.1752E-06"
        iyy="0.0021982"
        iyz="-1.1047E-09"
        izz="0.0011544" />
    </inertial>
    <visual>
      <origin
        xyz="0 0 0"
        rpy="0 0 0" />
      <geometry>
        <mesh
          filename="package://sp_description/meshes/engineer_framed/engineer_chassis/link3_fr.STL" />
      </geometry>
      <material
        name="">
        <color
          rgba="0.69804 0.69804 0.69804 1" />
      </material>
    </visual>
    <collision>
      <origin
        xyz="0 0 0"
        rpy="0 0 0" />
      <geometry>
        <mesh
          filename="package://sp_description/meshes/engineer_framed/engineer_chassis/link3_fr.STL" />
      </geometry>
    </collision>
  </link>
  <joint
    name="joint3_fr"
    type="continuous">
    <origin
      xyz="0.1917 -0.2005 0.077"
      rpy="0 0 0" />
    <parent
      link="base_link" />
    <child
      link="link3_fr" />
    <axis
      xyz="0 -1 0" />
    <limit
      lower="0"
      upper="0"
      effort="0"
      velocity="0" />
  </joint>
  <link
    name="link4_fl">
    <inertial>
      <origin
        xyz="-0.00020142 0.023775 1.3729E-05"
        rpy="0 0 0" />
      <mass
        value="0.70951" />
      <inertia
        ixx="0.0011576"
        ixy="1.6063E-10"
        ixz="1.2997E-06"
        iyy="0.0022157"
        iyz="1.7081E-09"
        izz="0.0011719" />
    </inertial>
    <visual>
      <origin
        xyz="0 0 0"
        rpy="0 0 0" />
      <geometry>
        <mesh
          filename="package://sp_description/meshes/engineer_framed/engineer_chassis/link4_fl.STL" />
      </geometry>
      <material
        name="">
        <color
          rgba="0.69804 0.69804 0.69804 1" />
      </material>
    </visual>
    <collision>
      <origin
        xyz="0 0 0"
        rpy="0 0 0" />
      <geometry>
        <mesh
          filename="package://sp_description/meshes/engineer_framed/engineer_chassis/link4_fl.STL" />
      </geometry>
    </collision>
  </link>
  <joint
    name="joint4_fl"
    type="continuous">
    <origin
      xyz="0.19167 0.2005 0.077106"
      rpy="0 0 0" />
    <parent
      link="base_link" />
    <child
      link="link4_fl" />
    <axis
      xyz="0 1 0" />
  </joint>
  </xacro:macro>
</robot>